<?xml version="1.0" ?>
<!-- This file is originated from gazebo_auv_sim package by Gigmus: https://github.com/gigimus/gazebo-auv-sim -->
<sdf version="1.4">
    <model name="gripper">
        <link name="palm">
            <gravity>false</gravity>
            <inertial>
                <mass>0.01</mass>
            </inertial>
            <visual name='palm_vis'>
                <geometry>
                    <box>
                        <size>0.2 1 0.2</size>
                    </box>
                </geometry>
            </visual>

            <collision name='palm_col'>
                <geometry>
                    <box>
                        <size>0.2 1 0.2</size>
                    </box>
                </geometry>
            </collision>
        </link>

        <link name="left_finger">
            <gravity>false</gravity>
            <inertial>
                <mass>1</mass>
            </inertial>

            <pose>0.5 -0.5 0 0 0 0</pose>

            <visual name='left_finger_vis'>
                <geometry>
                    <box>
                        <size>0.5 0.2 0.2</size>
                    </box>
                </geometry>
            </visual>

            <collision name='left_finger_col'>
                <geometry>
                    <box>
                        <size>0.5 0.2 0.2</size>
                    </box>
                </geometry>
            </collision>
        </link>

        <link name="right_finger">
            <gravity>false</gravity>
            <inertial>
                <mass>1</mass>
            </inertial>

            <pose>0.5 0.5 0 0 0 0</pose>

            <visual name='right_finger_vis'>
                <geometry>
                    <box>
                        <size>0.5 0.2 0.2</size>
                    </box>
                </geometry>
            </visual>

            <collision name='right_finger_col'>
                <geometry>
                    <box>
                        <size>0.5 0.2 0.2</size>
                    </box>
                </geometry>
            </collision>
        </link>

        <joint name="l_finger_palm" type="prismatic">
            <child>left_finger</child>
            <parent>palm</parent>
            <axis>
                <limit>
                    <lower>-0.5</lower>
                    <upper>0.5</upper>
                </limit>
                <xyz>1 0 0</xyz>
            </axis>
        </joint>

        <joint name="r_finger_palm" type="prismatic">
            <child>right_finger</child>
            <parent>palm</parent>
            <axis>
                <limit>
                    <lower>-0.5</lower>
                    <upper>0.5</upper>
                </limit>
                <xyz>1 0 0</xyz>
            </axis>
        </joint>

        <gripper name="grasping">
            <!-- <grasp_check> -->
                <!-- <attach_steps>20</attach_steps> -->
                <!-- <detach_steps>40</detach_steps> -->
                <!-- <min_contact_count>1</min_contact_count> -->
            <!-- </grasp_check> -->
            <gripper_link>right_finger</gripper_link>
            <gripper_link>left_finger</gripper_link>
            <palm_link>palm</palm_link>
        </gripper>
    </model>
</sdf>
