<?xml version="1.0" ?>
<!-- =================================================================================== -->
<!-- |    This document was autogenerated by xacro from airbot5.xacro                  | -->
<!-- |    EDITING THIS FILE BY HAND IS NOT RECOMMENDED                                 | -->
<!-- =================================================================================== -->
<robot name="Airbotwith2dofarm" xmlns:xacro="http://www.ros.org/wiki/xacro">
  <!-- Constants -->
  <!--xacro:property name="pi" value="3.1415926535897931" /-->
  <!-- Arm base wrt Quad -->
  <!-- Arm Lengths -->
  <!--Structural Properties-->
  <link name="baselink"/>
  <link name="airbase">
    <visual>
      <origin rpy="0 0 0" xyz="0.0 0.0 0.0"/>
      <geometry>
        <mesh filename="model://airbot/meshes/quadrotor_base.dae"/>
        <!--box size="0.44 0.44 0.1632"/-->
      </geometry>
      <material name="red">
        <color rgba="0.8 0 0 1"/>
      </material>
    </visual>
    <inertial>
      <mass value="1.4"/>
      <inertia ixx="0.0256939946667" ixy="0.0" ixz="0.0" iyy="0.0256939946667" iyz="0.0" izz="0.0451733333333"/>
      <!--mass value="${m0}"/>
      <inertia ixx="${m0*4.32e-3}" ixy="0.0" ixz="0.0" iyy="${m0*4.32e-3}" iyz="0.0" izz="${m0*8.41e-3}"/-->
    </inertial>
  </link>
  <link name="link1">
    <visual>
      <origin rpy="0 0 0" xyz="0.0 0.0 0.0875"/>
      <material name="blue">
        <color rgba="0 0 0.8 1"/>
      </material>
      <geometry>
        <box size="0.02 0.02 0.175"/>
      </geometry>
    </visual>
    <inertial>
      <origin rpy="0 0 0" xyz="0.0 0.0 0.0"/>
      <!-- Since motors are heavy they constitute most weight-->
      <mass value="0.1"/>
      <inertia ixx="4.16666666667e-05" ixy="0.0" ixz="0.0" iyy="4.16666666667e-05" iyz="0.0" izz="4.16666666667e-05"/>
    </inertial>
  </link>
  <link name="link2">
    <visual>
      <origin rpy="0 0 0" xyz="0.0 0.0 0.21"/>
      <geometry>
        <box size="0.02 0.02 0.42"/>
      </geometry>
      <material name="red">
        <color rgba="0.8 0 0 1"/>
      </material>
    </visual>
    <inertial>
      <origin rpy="0 0 0" xyz="0.0 0.0 0.0"/>
      <mass value="0.1"/>
      <inertia ixx="4.16666666667e-05" ixy="0.0" ixz="0.0" iyy="4.16666666667e-05" iyz="0.0" izz="4.16666666667e-05"/>
    </inertial>
  </link>
  <link name="link3">
    <visual>
      <origin rpy="0 0 0" xyz="0.0 0.0 0.025"/>
      <geometry>
        <box size="0.02 0.1 0.05"/>
      </geometry>
      <material name="green">
        <color rgba="0 0.8 0 1"/>
      </material>
    </visual>
    <inertial>
      <origin rpy="0 0 0" xyz="0.0 0.0 0.025"/>
      <mass value="0.03"/>
      <inertia ixx="7.25e-06" ixy="0.0" ixz="0.0" iyy="7.25e-06" iyz="0.0" izz="2e-06"/>
    </inertial>
  </link>
  <!-- Joints -->
  <joint name="basetoairbase" type="fixed">
    <parent link="baselink"/>
    <child link="airbase"/>
    <origin rpy="0 0 0" xyz="0 0 0"/>
  </joint>
  <joint name="airbasetolink1" type="revolute">
    <parent link="airbase"/>
    <child link="link1"/>
    <origin rpy="0 0 0" xyz="0.0732 0 -0.1"/>
    <axis xyz="0 1 0"/>
    <!--limit effort="30" velocity="10.0" lower="-${360*degtorad}" upper="${360*degtorad}"/-->
    <limit effort="30" lower="1.30899693825" upper="2.87979326415" velocity="10.0"/>
  </joint>
  <joint name="link1tolink2" type="revolute">
    <parent link="link1"/>
    <child link="link2"/>
    <origin rpy="0 0 0" xyz="0.025 0 0.175"/>
    <axis xyz="0 1 0"/>
    <!--limit effort="30" velocity="10.0" lower="-${360*degtorad}" upper="${360*degtorad}"/-->
    <limit effort="30" lower="-1.5707963259" upper="3.1415926518" velocity="10.0"/>
  </joint>
  <joint name="link2tolink3" type="fixed">
    <parent link="link2"/>
    <child link="link3"/>
    <origin rpy="0 0 0" xyz="0 0 0.42"/>
  </joint>
</robot>

