<?xml version="1.0"?>
<sdf version="1.4">
  <world name="default">
    <!-- Light Source -->
    <light type="directional" name="sun">
      <cast_shadows>true</cast_shadows>
      <pose>0 0 5 0 0 0</pose>
      <diffuse>0.8 0.8 0.8 1</diffuse>
      <specular>0.2 0.2 0.2 1</specular>
      <attenuation>
        <range>1000</range>
        <constant>0.9</constant>
        <linear>0.01</linear>
        <quadratic>0.001</quadratic>
      </attenuation>
      <direction>1 1 -1</direction>
    </light>
    <model name="satellitewitharm">
      <include>
        <uri>model://satellite</uri>
      </include>
      <link name="palm">
        <pose>0.07 0 0.2 0 0 0</pose>
        <inertial>
          <mass>0.02</mass>
        </inertial>
        <visual name="palm_vis">
          <geometry>
            <box>
              <size>0.02 0.1 0.02</size>
            </box>
          </geometry>
        </visual>
        <collision name="palm_col">
          <geometry>
            <box>
              <size>0.02 0.1 0.02</size>
            </box>
          </geometry>
        </collision>
      </link>
      <link name="left_finger">
        <inertial>
          <mass>0.01</mass>
        </inertial>
        <pose>0.11 -0.05 0.2 0 0 0</pose>
        <visual name="left_finger_vis">
          <geometry>
            <box>
              <size>0.05 0.02 0.02</size>
            </box>
          </geometry>
        </visual>
        <collision name="left_finger_col">
          <geometry>
            <box>
              <size>0.05 0.02 0.02</size>
            </box>
          </geometry>
        </collision>
      </link>
      <link name="right_finger">
        <inertial>
          <mass>0.01</mass>
        </inertial>
        <pose>0.11 0.05 0.2 0 0 0</pose>
        <visual name="right_finger_vis">
          <geometry>
            <box>
              <size>0.05 0.02 0.02</size>
            </box>
          </geometry>
        </visual>
        <collision name="right_finger_col">
          <geometry>
            <box>
              <size>0.05 0.02 0.02</size>
            </box>
          </geometry>
        </collision>
      </link>
      <joint name="l_finger_palm" type="prismatic">
        <child>left_finger</child>
        <parent>palm</parent>
        <axis>
          <limit>
            <lower>-0.05</lower>
            <upper>0.05</upper>
          </limit>
          <xyz>0 1 0</xyz>
        </axis>
      </joint>
      <joint name="r_finger_palm" type="prismatic">
        <child>right_finger</child>
        <parent>palm</parent>
        <axis>
          <limit>
            <lower>-0.05</lower>
            <upper>0.05</upper>
          </limit>
          <xyz>0 1 0</xyz>
        </axis>
      </joint>
      <!--gripper name="grasping">
        <gripper_link>right_finger</gripper_link>
        <gripper_link>left_finger</gripper_link>
        <palm_link>palm</palm_link>
      </gripper-->
      <joint name="gripper_joint" type="revolute">
        <parent>satellite::link</parent>
        <child>palm</child>
        <axis>
          <xyz>0 1 0</xyz>
          <limit>
            <lower>0</lower>
            <upper>0</upper>
          </limit>
        </axis>
      </joint>
    </model>
    <physics type="ode">
      <gravity>0 0 0</gravity>
    </physics>
    <plugin name="gazebo_rosmatlab_bridge" filename="libgazebo_rosmatlab_bridge.so">
      <links>satellite::thruster1::link;satellite::thruster2::link;satellite::thruster3::link;satellite::thruster4::link;satellite::thruster5::link;satellite::thruster6::link;satellite::thruster7::link;satellite::thruster8::link;satellite::thruster9::link;satellite::thruster10::link;satellite::link</links>
      <joints>gripper_joint;l_finger_palm;r_finger_palm</joints>
    </plugin>
  </world>
</sdf>
